<?xml version="1.0" ?>
<!-- =================================================================================== -->
<!-- |    This document was autogenerated by xacro from ic120_gazebo.xacro             | -->
<!-- |    EDITING THIS FILE BY HAND IS NOT RECOMMENDED                                 | -->
<!-- =================================================================================== -->
<robot name="ic120">
  <!-- Base Link -->
  <link name="base_link"/>
  <joint name="base_joint" type="fixed">
    <parent link="base_link"/>
    <child link="body_link"/>
  </joint>
  <link name="body_link">
    <visual>
      <geometry>
        <mesh filename="package://ic120_description/meshes/ic120-body.dae"/>
      </geometry>
    </visual>
    <inertial>
      <origin rpy="0 0 0" xyz="0.8963 0.1313 1.35"/>
      <mass value="0.1"/>
      <inertia ixx="1.0" ixy="0.0" ixz="0.0" iyy="1.0" iyz="0.0" izz="1.0"/>
    </inertial>
  </link>
  <!-- left sprocket axis -->
  <joint name="sprocket_left_joint" type="continuous">
    <origin xyz="-2.35 1 0.65"/>
    <axis xyz="0 1 0"/>
    <parent link="body_link"/>
    <child link="left_sprocket_link"/>
  </joint>
  <link name="left_sprocket_link"/>
  <!-- right sprocket axis -->
  <joint name="sprocket_right_joint" type="continuous">
    <origin xyz="-2.35 -1 0.65"/>
    <axis xyz="0 1 0"/>
    <parent link="body_link"/>
    <child link="right_sprocket_link"/>
  </joint>
  <link name="right_sprocket_link"/>
  <!-- bucket axis -->
  <joint name="vessel_pin_joint" type="revolute">
    <origin xyz="-3.0153 0 0.94605"/>
    <axis xyz="0 1 0"/>
    <parent link="body_link"/>
    <child link="vessel_pin_link"/>
    <limit effort="30" lower="-1.1344640137963142" upper="0" velocity="6.159937255"/>
  </joint>
  <link name="vessel_pin_link">
    <visual>
      <geometry>
        <mesh filename="package://ic120_description/meshes/ic120-vessel.dae"/>
      </geometry>
    </visual>
    <inertial>
      <origin rpy="0 0 0" xyz="1.978 0.0181 0.773"/>
      <mass value="0.1"/>
      <inertia ixx="1.0" ixy="0.0" ixz="0.0" iyy="1.0" iyz="0.0" izz="1.0"/>
    </inertial>
  </link>
  <!-- cylinder outer axis -->
  <joint name="cylinder_head_joint" type="continuous">
    <origin xyz="-0.75792 0 0.73083"/>
    <axis xyz="0 1 0"/>
    <parent link="body_link"/>
    <child link="cylinder_head_link"/>
    <mimic joint="vessel_pin_joint" multiplier="-0.088"/>
  </joint>
  <link name="cylinder_head_link">
    <visual>
      <geometry>
        <mesh filename="package://ic120_description/meshes/ic120-cylinder1.dae"/>
      </geometry>
    </visual>
    <inertial>
      <origin rpy="0 0 0" xyz="-0.4842 0 0.1667"/>
      <mass value="0.03"/>
      <inertia ixx="1.0" ixy="0.0" ixz="0.0" iyy="1.0" iyz="0.0" izz="1.0"/>
    </inertial>
  </link>
  <!-- cylinder inner prismatic joint -->
  <joint name="cylinder_rod_prismatic_joint" type="prismatic">
    <origin xyz="0 0 0"/>
    <parent link="cylinder_head_link"/>
    <child link="cylinder_rod_link"/>
    <axis xyz="-1.4989 0 0.51788"/>
    <limit effort="30" lower="-1" upper="1" velocity="6.159937255"/>
    <mimic joint="vessel_pin_joint" multiplier="-0.7051788247763978"/>
  </joint>
  <link name="cylinder_rod_link">
    <visual>
      <geometry>
        <mesh filename="package://ic120_description/meshes/ic120-cylinder2.dae"/>
      </geometry>
    </visual>
    <inertial>
      <origin rpy="0 0 0" xyz="-0.8807 0 0.3033"/>
      <mass value="0.03"/>
      <inertia ixx="1.0" ixy="0.0" ixz="0.0" iyy="1.0" iyz="0.0" izz="1.0"/>
    </inertial>
  </link>
  <transmission name="tran1">
    <type>transmission_interface/SimpleTransmission</type>
    <joint name="vessel_pin_joint">
      <hardwareInterface>hardware_interface/EffortJointInterface</hardwareInterface>
    </joint>
    <actuator name="vessel_pin_joint_motor">
      <hardwareInterface>hardware_interface/EffortJointInterface</hardwareInterface>
      <mechanicalReduction>1</mechanicalReduction>
    </actuator>
  </transmission>
  <joint name="left_middle_wheel_joint" type="continuous">
    <origin rpy="-1.5707963267948966 0 0" xyz="0 2 0.5"/>
    <axis xyz="0 0 1"/>
    <parent link="base_link"/>
    <child link="left_middle_wheel_link"/>
  </joint>
  <transmission name="left_middle_wheel_trans">
    <type>transmission_interface/SimpleTransmission</type>
    <actuator name="{prefix}_motor">
      <mechanicalReduction>1</mechanicalReduction>
    </actuator>
    <joint name="left_middle_wheel_joint">
      <hardwareInterface>hardware_interface/VelocityJointInterface</hardwareInterface>
    </joint>
  </transmission>
  <link name="left_middle_wheel_link">
    <inertial>
      <origin rpy="0 0 0" xyz="0 0 0"/>
      <mass value="1"/>
      <inertia ixx="1" ixy="0.0" ixz="0.0" iyy="1" iyz="0.0" izz="1"/>
    </inertial>
    <collision>
      <geometry>
        <cylinder length="0.3" radius="0.5"/>
      </geometry>
    </collision>
  </link>
  <gazebo reference="left_middle_wheel_link">
    <mu1>10</mu1>
    <mu2>10</mu2>
    <kp>1000000.0</kp>
    <kd>1000</kd>
  </gazebo>
  <joint name="left_front_wheel_joint" type="continuous">
    <origin rpy="-1.5707963267948966 0 0" xyz="1.5 1 0.5"/>
    <axis xyz="0 0 1"/>
    <parent link="base_link"/>
    <child link="left_front_wheel_link"/>
  </joint>
  <link name="left_front_wheel_link">
    <inertial>
      <origin rpy="0 0 0" xyz="0 0 0"/>
      <mass value="1"/>
      <inertia ixx="1" ixy="0.0" ixz="0.0" iyy="1" iyz="0.0" izz="1"/>
    </inertial>
    <collision>
      <geometry>
        <cylinder length="0.3" radius="0.5"/>
      </geometry>
    </collision>
  </link>
  <gazebo reference="left_front_wheel_link">
    <mu1>0</mu1>
    <mu2>0</mu2>
  </gazebo>
  <joint name="left_rear_wheel_joint" type="continuous">
    <origin rpy="-1.5707963267948966 0 0" xyz="-1.5 1 0.5"/>
    <axis xyz="0 0 1"/>
    <parent link="base_link"/>
    <child link="left_rear_wheel_link"/>
  </joint>
  <link name="left_rear_wheel_link">
    <inertial>
      <origin rpy="0 0 0" xyz="0 0 0"/>
      <mass value="1"/>
      <inertia ixx="1" ixy="0.0" ixz="0.0" iyy="1" iyz="0.0" izz="1"/>
    </inertial>
    <collision>
      <geometry>
        <cylinder length="0.3" radius="0.5"/>
      </geometry>
    </collision>
  </link>
  <gazebo reference="left_rear_wheel_link">
    <mu1>0</mu1>
    <mu2>0</mu2>
  </gazebo>
  <joint name="right_middle_wheel_joint" type="continuous">
    <origin rpy="-1.5707963267948966 0 0" xyz="0 -2 0.5"/>
    <axis xyz="0 0 1"/>
    <parent link="base_link"/>
    <child link="right_middle_wheel_link"/>
  </joint>
  <transmission name="right_middle_wheel_trans">
    <type>transmission_interface/SimpleTransmission</type>
    <actuator name="/{prefix}_motor">
      <mechanicalReduction>1</mechanicalReduction>
    </actuator>
    <joint name="right_middle_wheel_joint">
      <hardwareInterface>hardware_interface/VelocityJointInterface</hardwareInterface>
    </joint>
  </transmission>
  <link name="right_middle_wheel_link">
    <visual>
      <geometry>
        <cylinder length="0.3" radius="0.5"/>
      </geometry>
    </visual>
    <inertial>
      <origin rpy="0 0 0" xyz="0 0 0"/>
      <mass value="1"/>
      <inertia ixx="1" ixy="0.0" ixz="0.0" iyy="1" iyz="0.0" izz="1"/>
    </inertial>
    <collision>
      <geometry>
        <cylinder length="0.3" radius="0.5"/>
      </geometry>
    </collision>
  </link>
  <gazebo reference="right_middle_wheel_link">
    <mu1>10</mu1>
    <mu2>10</mu2>
    <kp>1000000.0</kp>
    <kd>1000</kd>
  </gazebo>
  <joint name="right_front_wheel_joint" type="continuous">
    <origin rpy="-1.5707963267948966 0 0" xyz="1.5 -1 0.5"/>
    <axis xyz="0 0 1"/>
    <parent link="base_link"/>
    <child link="right_front_wheel_link"/>
  </joint>
  <link name="right_front_wheel_link">
    <inertial>
      <origin rpy="0 0 0" xyz="0 0 0"/>
      <mass value="1"/>
      <inertia ixx="1" ixy="0.0" ixz="0.0" iyy="1" iyz="0.0" izz="1"/>
    </inertial>
    <collision>
      <geometry>
        <cylinder length="0.3" radius="0.5"/>
      </geometry>
    </collision>
  </link>
  <gazebo reference="right_front_wheel_link">
    <mu1>0</mu1>
    <mu2>0</mu2>
  </gazebo>
  <joint name="right_rear_wheel_joint" type="continuous">
    <origin rpy="-1.5707963267948966 0 0" xyz="-1.5 -1 0.5"/>
    <axis xyz="0 0 1"/>
    <parent link="base_link"/>
    <child link="right_rear_wheel_link"/>
  </joint>
  <link name="right_rear_wheel_link">
    <inertial>
      <origin rpy="0 0 0" xyz="0 0 0"/>
      <mass value="1"/>
      <inertia ixx="1" ixy="0.0" ixz="0.0" iyy="1" iyz="0.0" izz="1"/>
    </inertial>
    <collision>
      <geometry>
        <cylinder length="0.3" radius="0.5"/>
      </geometry>
    </collision>
  </link>
  <gazebo reference="right_rear_wheel_link">
    <mu1>0</mu1>
    <mu2>0</mu2>
  </gazebo>
  <gazebo>
    <plugin filename="libgazebo_ros_control.so" name="gazebo_ros_control"/>
  </gazebo>
</robot>
